Workbook

Sheet GÜZERGAH TALEP
A1: SEFER ZAMAN / GÜZERGAH TALEP FORMU
A2: TALEP TARİHİ
A3: TALEP EDEN (AD & SOYAD) | C3: Erkan İPEK | G3: SAYFADA SADECE BEYAZ RENKLİ HÜCRELER DOLDURULACAKTIR !!
A4: BAĞLI OLDUĞU TUR | C4: Çukurova
A5: GÜZERGAH
A8: GİDİŞ | D8: TOPLAM SEYAHAT SÜRESİ | F8: → | G8: =IF(G11="","",IFERROR(SUM(E13:E100),"")) -> 0.75 | I8: DÖNÜŞ | L8: TOPLAM SEYAHAT SÜRESİ | N8: → | O8: =IF(O11="","",IFERROR(SUM(M13:M100),"")) -> 0.72916667
A10: DURAK SIRA NO | B10: DURAK KODU | C10: DURAK | D10: SÜRE | F10: KALKIŞ / VARIŞ SAATLERİ | I10: DURAK SIRA NO | J10: DURAK KODU | K10: DURAK | L10: SÜRE | N10: KALKIŞ / VARIŞ SAATLERİ
A11: =IF(C11="","",ROW()-10) -> 1 | B11: =IFERROR(IF(C11="","",VLOOKUP(C11,'DURAK İSİMLERİ'!$C:$D,2,0)),"") -> HT1 | C11: HATAY | D11: ANA DURAK KALKIŞ SAATİ → | G11: 0.58333333 | I11: =IF(K11="","",ROW()-10) -> 1 | J11: =IFERROR(IF(K11="","",VLOOKUP(K11,'DURAK İSİMLERİ'!$C:$D,2,0)),"") -> FH1 | K11: FETHİYE | L11: ANA DURAK KALKIŞ SAATİ → | O11: 0.64583333
A13: =IF(C13="","",A11+1) -> 2 | B13: =IFERROR(IF(C13="","",VLOOKUP(C13,'DURAK İSİMLERİ'!$C:$D,2,0)),"") -> QH1 | C13: KIRIKHAN | D13: SEYAHAT SÜRESİ → | E13: 0.020833333 | F13: VARIŞ → | G13: =IFERROR(IF(E13="","",SUM($G$11,$E$13:$E13)),"") -> 0.60416667 | I13: =IF(K13="","",I11+1) -> 2 | J13: =IFERROR(IF(K13="","",VLOOKUP(K13,'DURAK İSİMLERİ'!$C:$D,2,0)),"") -> AT1 | K13: ANTALYA | L13: SEYAHAT SÜRESİ → | M13: 0.125 | N13: VARIŞ → | O13: =IFERROR(IF(M13="","",SUM($O$11,$M$13:$M13)),"") -> 0.77083333
D14: PERON SÜRESİ → | E14: 0 | F14: KALKIŞ → | G14: =IFERROR(IF(E14="","",SUM($G$11,$E$13:$E14)),"") -> 0.60416667 | L14: PERON SÜRESİ → | M14: 0.020833333 | N14: KALKIŞ → | O14: =IFERROR(IF(M14="","",SUM($O$11,$M$13:$M14)),"") -> 0.79166667
A15: =IF(C15="","",A13+1) -> 3 | B15: =IFERROR(IF(C15="","",VLOOKUP(C15,'DURAK İSİMLERİ'!$C:$D,2,0)),"") | C15: İSKENDERUN | D15: SEYAHAT SÜRESİ → | E15: 0.038194444 | F15: VARIŞ → | G15: =IFERROR(IF(E15="","",SUM($G$11,$E$13:$E15)),"") -> 0.64236111 | I15: =IF(K15="","",I13+1) -> 3 | J15: =IFERROR(IF(K15="","",VLOOKUP(K15,'DURAK İSİMLERİ'!$C:$D,2,0)),"") -> SR1 | K15: SERİK | L15: SEYAHAT SÜRESİ → | M15: 0.027777778 | N15: VARIŞ → | O15: =IFERROR(IF(M15="","",SUM($O$11,$M$13:$M15)),"") -> 0.81944444
D16: PERON SÜRESİ → | E16: 0.0034722222 | F16: KALKIŞ → | G16: =IFERROR(IF(E16="","",SUM($G$11,$E$13:$E16)),"") -> 0.64583333 | L16: PERON SÜRESİ → | M16: 0.0034722222 | N16: KALKIŞ → | O16: =IFERROR(IF(M16="","",SUM($O$11,$M$13:$M16)),"") -> 0.82291667
A17: =IF(C17="","",A15+1) -> 4 | B17: =IFERROR(IF(C17="","",VLOOKUP(C17,'DURAK İSİMLERİ'!$C:$D,2,0)),"") -> PY1 | C17: PAYAS | D17: SEYAHAT SÜRESİ → | E17: 0.020833333 | F17: VARIŞ → | G17: =IFERROR(IF(E17="","",SUM($G$11,$E$13:$E17)),"") -> 0.66666667 | I17: =IF(K17="","",I15+1) -> 4 | J17: =IFERROR(IF(K17="","",VLOOKUP(K17,'DURAK İSİMLERİ'!$C:$D,2,0)),"") -> MN1 | K17: MANAVGAT | L17: SEYAHAT SÜRESİ → | M17: 0.027777778 | N17: VARIŞ → | O17: =IFERROR(IF(M17="","",SUM($O$11,$M$13:$M17)),"") -> 0.85069444
D18: PERON SÜRESİ → | E18: 0 | F18: KALKIŞ → | G18: =IFERROR(IF(E18="","",SUM($G$11,$E$13:$E18)),"") -> 0.66666667 | L18: PERON SÜRESİ → | M18: 0.0034722222 | N18: KALKIŞ → | O18: =IFERROR(IF(M18="","",SUM($O$11,$M$13:$M18)),"") -> 0.85416667
A19: =IF(C19="","",A17+1) -> 5 | B19: =IFERROR(IF(C19="","",VLOOKUP(C19,'DURAK İSİMLERİ'!$C:$D,2,0)),"") -> DT1 | C19: DÖRTYOL | D19: SEYAHAT SÜRESİ → | E19: 0.010416667 | F19: VARIŞ → | G19: =IFERROR(IF(E19="","",SUM($G$11,$E$13:$E19)),"") -> 0.67708333 | I19: =IF(K19="","",I17+1) -> 5 | J19: =IFERROR(IF(K19="","",VLOOKUP(K19,'DURAK İSİMLERİ'!$C:$D,2,0)),"") -> AL1 | K19: ALANYA | L19: SEYAHAT SÜRESİ → | M19: 0.038194444 | N19: VARIŞ → | O19: =IFERROR(IF(M19="","",SUM($O$11,$M$13:$M19)),"") -> 0.89236111
D20: PERON SÜRESİ → | E20: 0 | F20: KALKIŞ → | G20: =IFERROR(IF(E20="","",SUM($G$11,$E$13:$E20)),"") -> 0.67708333 | L20: PERON SÜRESİ → | M20: 0.0034722222 | N20: KALKIŞ → | O20: =IFERROR(IF(M20="","",SUM($O$11,$M$13:$M20)),"") -> 0.89583333
A21: =IF(C21="","",A19+1) -> 6 | B21: =IFERROR(IF(C21="","",VLOOKUP(C21,'DURAK İSİMLERİ'!$C:$D,2,0)),"") -> CY1 | C21: CEYHAN | D21: SEYAHAT SÜRESİ → | E21: 0.027777778 | F21: VARIŞ → | G21: =IFERROR(IF(E21="","",SUM($G$11,$E$13:$E21)),"") -> 0.70486111 | I21: =IF(K21="","",I19+1) -> 6 | J21: =IFERROR(IF(K21="","",VLOOKUP(K21,'DURAK İSİMLERİ'!$C:$D,2,0)),"") | K21: GAZİAPAŞA | L21: SEYAHAT SÜRESİ → | M21: 0.038194444 | N21: VARIŞ → | O21: =IFERROR(IF(M21="","",SUM($O$11,$M$13:$M21)),"") -> 0.93402778
D22: PERON SÜRESİ → | E22: 0.0034722222 | F22: KALKIŞ → | G22: =IFERROR(IF(E22="","",SUM($G$11,$E$13:$E22)),"") -> 0.70833333 | L22: PERON SÜRESİ → | M22: 0.0034722222 | N22: KALKIŞ → | O22: =IFERROR(IF(M22="","",SUM($O$11,$M$13:$M22)),"") -> 0.9375
A23: =IF(C23="","",A21+1) -> 7 | B23: =IFERROR(IF(C23="","",VLOOKUP(C23,'DURAK İSİMLERİ'!$C:$D,2,0)),"") -> AD1 | C23: ADANA | D23: SEYAHAT SÜRESİ → | E23: 0.038194444 | F23: VARIŞ → | G23: =IFERROR(IF(E23="","",SUM($G$11,$E$13:$E23)),"") -> 0.74652778 | I23: =IF(K23="","",I21+1) -> 7 | J23: =IFERROR(IF(K23="","",VLOOKUP(K23,'DURAK İSİMLERİ'!$C:$D,2,0)),"") | K23: GAZİAPAŞA ÇELİKLER | L23: SEYAHAT SÜRESİ → | M23: 0.0034722222 | N23: VARIŞ → | O23: =IFERROR(IF(M23="","",SUM($O$11,$M$13:$M23)),"") -> 0.94097222
D24: PERON SÜRESİ → | E24: 0.0034722222 | F24: KALKIŞ → | G24: =IFERROR(IF(E24="","",SUM($G$11,$E$13:$E24)),"") -> 0.75 | L24: PERON SÜRESİ → | M24: 0.020833333 | N24: KALKIŞ → | O24: =IFERROR(IF(M24="","",SUM($O$11,$M$13:$M24)),"") -> 0.96180556
A25: =IF(C25="","",A23+1) -> 8 | B25: =IFERROR(IF(C25="","",VLOOKUP(C25,'DURAK İSİMLERİ'!$C:$D,2,0)),"") -> TS1 | C25: TARSUS | D25: SEYAHAT SÜRESİ → | E25: 0.03125 | F25: VARIŞ → | G25: =IFERROR(IF(E25="","",SUM($G$11,$E$13:$E25)),"") -> 0.78125 | I25: =IF(K25="","",I23+1) -> 8 | J25: =IFERROR(IF(K25="","",VLOOKUP(K25,'DURAK İSİMLERİ'!$C:$D,2,0)),"") -> DB1 | K25: ANAMUR | L25: SEYAHAT SÜRESİ → | M25: 0.0375 | N25: VARIŞ → | O25: =IFERROR(IF(M25="","",SUM($O$11,$M$13:$M25)),"") -> 0.99930556
D26: PERON SÜRESİ → | E26: 0 | F26: KALKIŞ → | G26: =IFERROR(IF(E26="","",SUM($G$11,$E$13:$E26)),"") -> 0.78125 | L26: PERON SÜRESİ → | M26: 0 | N26: KALKIŞ → | O26: =IFERROR(IF(M26="","",SUM($O$11,$M$13:$M26)),"") -> 0.99930556
A27: =IF(C27="","",A25+1) -> 9 | B27: =IFERROR(IF(C27="","",VLOOKUP(C27,'DURAK İSİMLERİ'!$C:$D,2,0)),"") -> ME1 | C27: MERSİN | D27: SEYAHAT SÜRESİ → | E27: 0.027777778 | F27: VARIŞ → | G27: =IFERROR(IF(E27="","",SUM($G$11,$E$13:$E27)),"") -> 0.80902778 | I27: =IF(K27="","",I25+1) -> 9 | J27: =IFERROR(IF(K27="","",VLOOKUP(K27,'DURAK İSİMLERİ'!$C:$D,2,0)),"") | K27: BREAK MOLA | L27: SEYAHAT SÜRESİ → | M27: 0.073611111 | N27: VARIŞ → | O27: =IFERROR(IF(M27="","",SUM($O$11,$M$13:$M27)),"") -> 1.0729167
D28: PERON SÜRESİ → | E28: 0.0034722222 | F28: KALKIŞ → | G28: =IFERROR(IF(E28="","",SUM($G$11,$E$13:$E28)),"") -> 0.8125 | L28: PERON SÜRESİ → | M28: 0.020833333 | N28: KALKIŞ → | O28: =IFERROR(IF(M28="","",SUM($O$11,$M$13:$M28)),"") -> 1.09375
A29: =IF(C29="","",A27+1) -> 10 | B29: =IFERROR(IF(C29="","",VLOOKUP(C29,'DURAK İSİMLERİ'!$C:$D,2,0)),"") -> EM1 | C29: ERDEMLİ | D29: SEYAHAT SÜRESİ → | E29: 0.020833333 | F29: VARIŞ → | G29: =IFERROR(IF(E29="","",SUM($G$11,$E$13:$E29)),"") -> 0.83333333 | I29: =IF(K29="","",I27+1) -> 10 | J29: =IFERROR(IF(K29="","",VLOOKUP(K29,'DURAK İSİMLERİ'!$C:$D,2,0)),"") -> FE1 | K29: SİLİFKE | L29: SEYAHAT SÜRESİ → | M29: 0.020833333 | N29: VARIŞ → | O29: =IFERROR(IF(M29="","",SUM($O$11,$M$13:$M29)),"") -> 1.1145833
D30: PERON SÜRESİ → | E30: 0 | F30: KALKIŞ → | G30: =IFERROR(IF(E30="","",SUM($G$11,$E$13:$E30)),"") -> 0.83333333 | L30: PERON SÜRESİ → | M30: 0 | N30: KALKIŞ → | O30: =IFERROR(IF(M30="","",SUM($O$11,$M$13:$M30)),"") -> 1.1145833
A31: =IF(C31="","",A29+1) -> 11 | B31: =IFERROR(IF(C31="","",VLOOKUP(C31,'DURAK İSİMLERİ'!$C:$D,2,0)),"") -> FE1 | C31: SİLİFKE | D31: SEYAHAT SÜRESİ → | E31: 0.020833333 | F31: VARIŞ → | G31: =IFERROR(IF(E31="","",SUM($G$11,$E$13:$E31)),"") -> 0.85416667 | I31: =IF(K31="","",I29+1) -> 11 | J31: =IFERROR(IF(K31="","",VLOOKUP(K31,'DURAK İSİMLERİ'!$C:$D,2,0)),"") -> EM1 | K31: ERDEMLİ | L31: SEYAHAT SÜRESİ → | M31: 0.020833333 | N31: VARIŞ → | O31: =IFERROR(IF(M31="","",SUM($O$11,$M$13:$M31)),"") -> 1.1354167
D32: PERON SÜRESİ → | E32: 0 | F32: KALKIŞ → | G32: =IFERROR(IF(E32="","",SUM($G$11,$E$13:$E32)),"") -> 0.85416667 | L32: PERON SÜRESİ → | M32: 0 | N32: KALKIŞ → | O32: =IFERROR(IF(M32="","",SUM($O$11,$M$13:$M32)),"") -> 1.1354167
A33: =IF(C33="","",A31+1) -> 12 | B33: =IFERROR(IF(C33="","",VLOOKUP(C33,'DURAK İSİMLERİ'!$C:$D,2,0)),"") | C33: BREAK MOLA | D33: SEYAHAT SÜRESİ → | E33: 0.0625 | F33: VARIŞ → | G33: =IFERROR(IF(E33="","",SUM($G$11,$E$13:$E33)),"") -> 0.91666667 | I33: =IF(K33="","",I31+1) -> 12 | J33: =IFERROR(IF(K33="","",VLOOKUP(K33,'DURAK İSİMLERİ'!$C:$D,2,0)),"") -> ME1 | K33: MERSİN | L33: SEYAHAT SÜRESİ → | M33: 0.03125 | N33: VARIŞ → | O33: =IFERROR(IF(M33="","",SUM($O$11,$M$13:$M33)),"") -> 1.1666667
D34: PERON SÜRESİ → | E34: 0.020833333 | F34: KALKIŞ → | G34: =IFERROR(IF(E34="","",SUM($G$11,$E$13:$E34)),"") -> 0.9375 | L34: PERON SÜRESİ → | M34: 0 | N34: KALKIŞ → | O34: =IFERROR(IF(M34="","",SUM($O$11,$M$13:$M34)),"") -> 1.1666667
A35: =IF(C35="","",A33+1) -> 13 | B35: =IFERROR(IF(C35="","",VLOOKUP(C35,'DURAK İSİMLERİ'!$C:$D,2,0)),"") -> DB1 | C35: ANAMUR | D35: SEYAHAT SÜRESİ → | E35: 0.0625 | F35: VARIŞ → | G35: =IFERROR(IF(E35="","",SUM($G$11,$E$13:$E35)),"") -> 1 | I35: =IF(K35="","",I33+1) -> 13 | J35: =IFERROR(IF(K35="","",VLOOKUP(K35,'DURAK İSİMLERİ'!$C:$D,2,0)),"") -> TS1 | K35: TARSUS | L35: SEYAHAT SÜRESİ → | M35: 0.020833333 | N35: VARIŞ → | O35: =IFERROR(IF(M35="","",SUM($O$11,$M$13:$M35)),"") -> 1.1875
D36: PERON SÜRESİ → | E36: 0 | F36: KALKIŞ → | G36: =IFERROR(IF(E36="","",SUM($G$11,$E$13:$E36)),"") -> 1 | L36: PERON SÜRESİ → | M36: 0 | N36: KALKIŞ → | O36: =IFERROR(IF(M36="","",SUM($O$11,$M$13:$M36)),"") -> 1.1875
A37: =IF(C37="","",A35+1) -> 14 | B37: =IFERROR(IF(C37="","",VLOOKUP(C37,'DURAK İSİMLERİ'!$C:$D,2,0)),"") | C37: GAZİPAŞA ÇELİKLER MOLA | D37: SEYAHAT SÜRESİ → | E37: 0.041666667 | F37: VARIŞ → | G37: =IFERROR(IF(E37="","",SUM($G$11,$E$13:$E37)),"") -> 1.0416667 | I37: =IF(K37="","",I35+1) -> 14 | J37: =IFERROR(IF(K37="","",VLOOKUP(K37,'DURAK İSİMLERİ'!$C:$D,2,0)),"") -> AD1 | K37: ADANA | L37: SEYAHAT SÜRESİ → | M37: 0.03125 | N37: VARIŞ → | O37: =IFERROR(IF(M37="","",SUM($O$11,$M$13:$M37)),"") -> 1.21875
D38: PERON SÜRESİ → | E38: 0.020833333 | F38: KALKIŞ → | G38: =IFERROR(IF(E38="","",SUM($G$11,$E$13:$E38)),"") -> 1.0625 | L38: PERON SÜRESİ → | M38: 0.010416667 | N38: KALKIŞ → | O38: =IFERROR(IF(M38="","",SUM($O$11,$M$13:$M38)),"") -> 1.2291667
A39: =IF(C39="","",A37+1) -> 15 | B39: =IFERROR(IF(C39="","",VLOOKUP(C39,'DURAK İSİMLERİ'!$C:$D,2,0)),"") -> GP1 | C39: GAZİPAŞA | D39: SEYAHAT SÜRESİ → | E39: 0.0034722222 | F39: VARIŞ → | G39: =IFERROR(IF(E39="","",SUM($G$11,$E$13:$E39)),"") -> 1.0659722 | I39: =IF(K39="","",I37+1) -> 15 | J39: =IFERROR(IF(K39="","",VLOOKUP(K39,'DURAK İSİMLERİ'!$C:$D,2,0)),"") -> CY1 | K39: CEYHAN | L39: SEYAHAT SÜRESİ → | M39: 0.038194444 | N39: VARIŞ → | O39: =IFERROR(IF(M39="","",SUM($O$11,$M$13:$M39)),"") -> 1.2673611
D40: PERON SÜRESİ → | E40: 0.0034722222 | F40: KALKIŞ → | G40: =IFERROR(IF(E40="","",SUM($G$11,$E$13:$E40)),"") -> 1.0694444 | L40: PERON SÜRESİ → | M40: 0.0034722222 | N40: KALKIŞ → | O40: =IFERROR(IF(M40="","",SUM($O$11,$M$13:$M40)),"") -> 1.2708333
A41: =IF(C41="","",A39+1) -> 16 | B41: =IFERROR(IF(C41="","",VLOOKUP(C41,'DURAK İSİMLERİ'!$C:$D,2,0)),"") -> AL1 | C41: ALANYA | D41: SEYAHAT SÜRESİ → | E41: 0.038194444 | F41: VARIŞ → | G41: =IFERROR(IF(E41="","",SUM($G$11,$E$13:$E41)),"") -> 1.1076389 | I41: =IF(K41="","",I39+1) -> 16 | J41: =IFERROR(IF(K41="","",VLOOKUP(K41,'DURAK İSİMLERİ'!$C:$D,2,0)),"") -> DT1 | K41: DÖRTYOL | L41: SEYAHAT SÜRESİ → | M41: 0.03125 | N41: VARIŞ → | O41: =IFERROR(IF(M41="","",SUM($O$11,$M$13:$M41)),"") -> 1.3020833
D42: PERON SÜRESİ → | E42: 0.0069444444 | F42: KALKIŞ → | G42: =IFERROR(IF(E42="","",SUM($G$11,$E$13:$E42)),"") -> 1.1145833 | L42: PERON SÜRESİ → | M42: 0 | N42: KALKIŞ → | O42: =IFERROR(IF(M42="","",SUM($O$11,$M$13:$M42)),"") -> 1.3020833
A43: =IF(C43="","",A41+1) -> 17 | B43: =IFERROR(IF(C43="","",VLOOKUP(C43,'DURAK İSİMLERİ'!$C:$D,2,0)),"") -> MN1 | C43: MANAVGAT | D43: SEYAHAT SÜRESİ → | E43: 0.038194444 | F43: VARIŞ → | G43: =IFERROR(IF(E43="","",SUM($G$11,$E$13:$E43)),"") -> 1.1527778 | I43: =IF(K43="","",I41+1) -> 17 | J43: =IFERROR(IF(K43="","",VLOOKUP(K43,'DURAK İSİMLERİ'!$C:$D,2,0)),"") -> PY1 | K43: PAYAS | L43: SEYAHAT SÜRESİ → | M43: 0.010416667 | N43: VARIŞ → | O43: =IFERROR(IF(M43="","",SUM($O$11,$M$13:$M43)),"") -> 1.3125
D44: PERON SÜRESİ → | E44: 0.0034722222 | F44: KALKIŞ → | G44: =IFERROR(IF(E44="","",SUM($G$11,$E$13:$E44)),"") -> 1.15625 | L44: PERON SÜRESİ → | M44: 0 | N44: KALKIŞ → | O44: =IFERROR(IF(M44="","",SUM($O$11,$M$13:$M44)),"") -> 1.3125
...

Sheet YASAK EKLEME & KALDIRMA
A1: DURAKLAR ARASI YASAK EKLEME / KALDIRMA FORMU
A2: TALEP TARİHİ
A3: TALEP EDEN (AD & SOYAD)
A4: BAĞLI OLDUĞU TUR
B6: YASAK EKLENECEK / KALDIRILACAK DURAKLAR
A7: S.N. | B7: HAT KODU | C7: KALKIŞ DURAĞI | D7: VARIŞ DURAĞI | E7: YASAK EKLEME / KALDIRMA
A8: 1
A9: 2
A10: 3
A11: 4
A12: 5
A13: 6
A14: 7
A15: 8
A16: 9
A17: 10
A18: 11
A19: 12
... A57: 50

Sheet DURAK İSİMLERİ
A1: Kod | B1: Durak ismi | C1: Durak ismi | D1: Kod | E1: Enlem | F1: Boylam | G1: Enlem - Boylam | J1: YASAKLA
A2: IE1 | B2: İstanbul Esenler bus station | C2: 14 Evler Camii | D2: EV! | E2: 38.02953 | F2: 27.08082 | G2: =CONCATENATE(E2," - ",F2) -> 38,02953 - 27,08082 | J2: YASAKLAMA
A3: IA1 | B3: İstanbul Alibeyköy bus station | C3: Abdipaşa | D3: PS1 | E3: 41.52032 | F3: 32.55616 | G3: =CONCATENATE(E3," - ",F3) -> 41,52032 - 32,55616
A4: ID1 | B4: İstanbul Dudullu bus station | C4: Acıgöl | D4: GL1 | E4: 38.549228 | F4: 34.504216 | G4: =CONCATENATE(E4," - ",F4) -> 38,549228 - 34,504216
A5: AR1 | B5: Ankara bus station | C5: Acıpayam | D5: QX1 | E5: 37.428709 | F5: 29.352137 | G5: =CONCATENATE(E5," - ",F5) -> 37,428709 - 29,352137
A6: IZ1 | B6: Izmir bus station | C6: Acipayam | D6: AP! | E6: 37.78465 | F6: 29.0911 | G6: =CONCATENATE(E6," - ",F6) -> 37,78465 - 29,0911
A7: GE1 | B7: Gebze bus station | C7: Adalya Dinlenme Tesisi | D7: AD3 | E7: 38.523492 | F7: 30.220352 | G7: =CONCATENATE(E7," - ",F7) -> 38,523492 - 30,220352
A8: YL1 | B8: Yalova bus station | C8: Adana | D8: AD1 | E8: 36.997043 | F8: 35.262125 | G8: =CONCATENATE(E8," - ",F8) -> 36,9970433171 - 35,2621250552
A9: BU1 | B9: Bursa bus station | C9: Adliye Kavşağı | D9: AD! | E9: 37.950323 | F9: 32.509435 | G9: =CONCATENATE(E9," - ",F9) -> 37,950323 - 32,509435
A10: BL1 | B10: Balıkesir bus station | C10: Adrasan Bölge Trafik | D10: AR! | E10: 36.363807 | F10: 30.303592 | G10: =CONCATENATE(E10," - ",F10) -> 36,363807 - 30,303592
A11: AKH | B11: Akhisar - DO NOT USE | C11: Afyon | D11: AF1 | E11: 38.790436 | F11: 30.510664 | G11: =CONCATENATE(E11," - ",F11) -> 38,790436 - 30,510664
A12: MANISA | B12: Manisa | C12: Afyon Kamil Koç Dinlenme Tesisi | D12: AF3 | E12: 38.790436 | F12: 30.510664 | G12: =CONCATENATE(E12," - ",F12) -> 38,790436 - 30,510664
A13: SK1 | B13: Sakarya bus station | C13: Ağaçlı | D13: AG! | E13: 38.358341 | F13: 33.983653 | G13: =CONCATENATE(E13," - ",F13) -> 38,358341 - 33,983653
A14: DZ1 | B14: Düzce bus station | C14: Ağaçlı Dinlenme Tesisi | D14: AG3 | E14: 38.386175 | F14: 33.993918 | G14: =CONCATENATE(E14," - ",F14) -> 38,3861748964381 - 33,9939180823706
... A802: MD3 | B802: Mengen Lezzet Dünyası rest station | C802: Zorlu Park Dinlenme Tesisi | D802: ZP3 | E802: 41.14318 | F802: 37.147881 | G802: =CONCATENATE(E802," - ",F802) -> 41,14318044 - 37,14788118
